<?xml version="1.0" ?>
<robot name="kuka_kr16" xmlns:xacro="http://wiki.ros.org/xacro">
<xacro:property name="prefix" value="lundgren_" />
<!--Macros -->
  <xacro:macro name="link_macro" params="link_name">
    <link name="${prefix}${link_name}">
      <visual>
        <geometry>
          <mesh filename="package://felix_lundgren/meshes/visual/${link_name}.dae"/>
        </geometry>
      </visual>
      <collision>
        <geometry>
          <mesh filename="package://felix_lundgren/meshes/collision/${link_name}.stl"/>
        </geometry>
      </collision>
    </link>
  </xacro:macro>

  <xacro:macro name="joints" >
    <!-- joint 1 (A1) -->
    <joint name="${prefix}joint_a1" type="revolute">
      <origin xyz="0 0 0.675" />
      <parent link="${prefix}base_link"/>
      <child link="${prefix}link_1"/>
      <axis xyz="0 0 -1"/>
      <limit effort="0" lower="${radians(-185)}" upper="${radians(185)}" velocity="${radians(156)}"/>
    </joint>
    <!-- joint 2 (A2) -->
    <joint name="${prefix}joint_a2" type="revolute">
      <origin xyz="0.26 0 0" />
      <parent link="${prefix}link_1"/>
      <child link="${prefix}link_2"/>
      <axis xyz="0 1 0"/>
      <limit effort="0" lower="${radians(-155)}" upper="${radians(35)}" velocity="${radians(156)}"/>
    </joint>
    <!-- joint 3 (A3) -->
    <joint name="${prefix}joint_a3" type="revolute">
      <origin xyz="0.68 0 0" />
      <parent link="${prefix}link_2"/>
      <child link="${prefix}link_3"/>
      <axis xyz="0 1 0"/>
      <limit effort="0" lower="${radians(-130)}" upper="${radians(154)}" velocity="${radians(156)}"/>
    </joint>
    <!-- joint 4 (A4) -->
    <joint name="${prefix}joint_a4" type="revolute">
      <origin xyz="0.67 0 -0.035" />
      <parent link="${prefix}link_3"/>
      <child link="${prefix}link_4"/>
      <axis xyz="-1 0 0"/>
      <limit effort="0" lower="${radians(-350)}" upper="${radians(350)}" velocity="${radians(330)}"/>
    </joint>
    <!-- joint 5 (A5) -->
    <joint name="${prefix}joint_a5" type="revolute">
      <origin xyz="0 0 0" rpy="0 0 0"/>
      <parent link="${prefix}link_4"/>
      <child link="${prefix}link_5"/>
      <axis xyz="0 1 0"/>
      <limit effort="0" lower="${radians(-130)}" upper="${radians(130)}" velocity="${radians(330)}"/>
    </joint>
    <!-- joint 6 (A6) -->
    <joint name="${prefix}joint_a6" type="revolute">
      <origin xyz="0 0 0" rpy="0 0 0"/>
      <parent link="${prefix}link_5"/>
      <child link="${prefix}link_6"/>
      <axis xyz="-1 0 0"/>
      <limit effort="0" lower="${radians(-350)}" upper="${radians(350)}" velocity="${radians(615)}"/>
    </joint>
    <!-- tool frame - fixed frame -->
    <joint name="${prefix}joint_a6-tool0" type="fixed">
      <parent link="${prefix}link_6"/>
      <child link="${prefix}tool0"/>
      <origin xyz="0.158 0 0" rpy="0 ${radians(90)} 0"/>
    </joint>
    <!-- END JOINTS -->

    <!-- ROS base_link to KUKA $ROBROOT coordinate system transform -->
    <link name="${prefix}base"/>
    <joint name="${prefix}base_link-base" type="fixed">
      <parent link="${prefix}base"/>
      <child link="${prefix}base_link"/>
    </joint>
  </xacro:macro>
<!-- LINKS -->
  <xacro:link_macro link_name="base_link" />
  <xacro:link_macro link_name="link_1" />
  <xacro:link_macro link_name="link_2" />
  <xacro:link_macro link_name="link_3" />
  <xacro:link_macro link_name="link_4" />
  <xacro:link_macro link_name="link_5" />
  <xacro:link_macro link_name="link_6" />
  <link name="${prefix}tool0" />
  <!-- END LINKS -->
<!-- JOINTS -->
  <xacro:joints />
</robot>

